{"name": "Navigate through different pages", "status": "broken", "statusDetails": {"message": "urllib3.exceptions.MaxRetryError: HTTPConnectionPool(host='localhost', port=58484): Max retries exceeded with url: /session/cbbd60d976809705537c388a7c0f7b29/url (Caused by NewConnectionError('<urllib3.connection.HTTPConnection object at 0x1041841d0>: Failed to establish a new connection: [Errno 61] Connection refused'))\n", "trace": "  File \"/opt/anaconda3/lib/python3.12/site-packages/behave/model.py\", line 1329, in run\n    match.run(runner.context)\n  File \"/opt/anaconda3/lib/python3.12/site-packages/behave/matchers.py\", line 98, in run\n    self.func(context, *args, **kwargs)\n  File \"features/steps/test_steps.py\", line 100, in step_redirected_to_products_page\n    print(f\"❌ ERROR: Expected 'inventory.html' but got {context.driver.current_url}\")\n                                                         ^^^^^^^^^^^^^^^^^^^^^^^^^^\n  File \"/opt/anaconda3/lib/python3.12/site-packages/selenium/webdriver/remote/webdriver.py\", line 470, in current_url\n    return self.execute(Command.GET_CURRENT_URL)[\"value\"]\n           ^^^^^^^^^^^^^^^^^^^^^^^^^^^^^^^^^^^^^\n  File \"/opt/anaconda3/lib/python3.12/site-packages/selenium/webdriver/remote/webdriver.py\", line 378, in execute\n    response = self.command_executor.execute(driver_command, params)\n               ^^^^^^^^^^^^^^^^^^^^^^^^^^^^^^^^^^^^^^^^^^^^^^^^^^^^^\n  File \"/opt/anaconda3/lib/python3.12/site-packages/selenium/webdriver/remote/remote_connection.py\", line 391, in execute\n    return self._request(command_info[0], url, body=data)\n           ^^^^^^^^^^^^^^^^^^^^^^^^^^^^^^^^^^^^^^^^^^^^^^\n  File \"/opt/anaconda3/lib/python3.12/site-packages/selenium/webdriver/remote/remote_connection.py\", line 415, in _request\n    response = self._conn.request(method, url, body=body, headers=headers, timeout=self._client_config.timeout)\n               ^^^^^^^^^^^^^^^^^^^^^^^^^^^^^^^^^^^^^^^^^^^^^^^^^^^^^^^^^^^^^^^^^^^^^^^^^^^^^^^^^^^^^^^^^^^^^^^^\n  File \"/opt/anaconda3/lib/python3.12/site-packages/urllib3/_request_methods.py\", line 135, in request\n    return self.request_encode_url(\n           ^^^^^^^^^^^^^^^^^^^^^^^^\n  File \"/opt/anaconda3/lib/python3.12/site-packages/urllib3/_request_methods.py\", line 182, in request_encode_url\n    return self.urlopen(method, url, **extra_kw)\n           ^^^^^^^^^^^^^^^^^^^^^^^^^^^^^^^^^^^^^\n  File \"/opt/anaconda3/lib/python3.12/site-packages/urllib3/poolmanager.py\", line 443, in urlopen\n    response = conn.urlopen(method, u.request_uri, **kw)\n               ^^^^^^^^^^^^^^^^^^^^^^^^^^^^^^^^^^^^^^^^^\n  File \"/opt/anaconda3/lib/python3.12/site-packages/urllib3/connectionpool.py\", line 873, in urlopen\n    return self.urlopen(\n           ^^^^^^^^^^^^^\n  File \"/opt/anaconda3/lib/python3.12/site-packages/urllib3/connectionpool.py\", line 873, in urlopen\n    return self.urlopen(\n           ^^^^^^^^^^^^^\n  File \"/opt/anaconda3/lib/python3.12/site-packages/urllib3/connectionpool.py\", line 873, in urlopen\n    return self.urlopen(\n           ^^^^^^^^^^^^^\n  File \"/opt/anaconda3/lib/python3.12/site-packages/urllib3/connectionpool.py\", line 843, in urlopen\n    retries = retries.increment(\n              ^^^^^^^^^^^^^^^^^^\n  File \"/opt/anaconda3/lib/python3.12/site-packages/urllib3/util/retry.py\", line 519, in increment\n    raise MaxRetryError(_pool, url, reason) from reason  # type: ignore[arg-type]\n    ^^^^^^^^^^^^^^^^^^^^^^^^^^^^^^^^^^^^^^^^^^^^^^^^^^^\n"}, "steps": [{"name": "Given I am on the homepage", "status": "passed", "start": 1739642294235, "stop": 1739642295138}, {"name": "When I click on the \"Products\" page", "status": "passed", "start": 1739642295138, "stop": 1739642300334}, {"name": "Then I should be redirected to the products page", "status": "broken", "statusDetails": {"message": "urllib3.exceptions.MaxRetryError: HTTPConnectionPool(host='localhost', port=58484): Max retries exceeded with url: /session/cbbd60d976809705537c388a7c0f7b29/url (Caused by NewConnectionError('<urllib3.connection.HTTPConnection object at 0x1041841d0>: Failed to establish a new connection: [Errno 61] Connection refused'))\n", "trace": "  File \"/opt/anaconda3/lib/python3.12/site-packages/behave/model.py\", line 1329, in run\n    match.run(runner.context)\n  File \"/opt/anaconda3/lib/python3.12/site-packages/behave/matchers.py\", line 98, in run\n    self.func(context, *args, **kwargs)\n  File \"features/steps/test_steps.py\", line 100, in step_redirected_to_products_page\n    print(f\"❌ ERROR: Expected 'inventory.html' but got {context.driver.current_url}\")\n                                                         ^^^^^^^^^^^^^^^^^^^^^^^^^^\n  File \"/opt/anaconda3/lib/python3.12/site-packages/selenium/webdriver/remote/webdriver.py\", line 470, in current_url\n    return self.execute(Command.GET_CURRENT_URL)[\"value\"]\n           ^^^^^^^^^^^^^^^^^^^^^^^^^^^^^^^^^^^^^\n  File \"/opt/anaconda3/lib/python3.12/site-packages/selenium/webdriver/remote/webdriver.py\", line 378, in execute\n    response = self.command_executor.execute(driver_command, params)\n               ^^^^^^^^^^^^^^^^^^^^^^^^^^^^^^^^^^^^^^^^^^^^^^^^^^^^^\n  File \"/opt/anaconda3/lib/python3.12/site-packages/selenium/webdriver/remote/remote_connection.py\", line 391, in execute\n    return self._request(command_info[0], url, body=data)\n           ^^^^^^^^^^^^^^^^^^^^^^^^^^^^^^^^^^^^^^^^^^^^^^\n  File \"/opt/anaconda3/lib/python3.12/site-packages/selenium/webdriver/remote/remote_connection.py\", line 415, in _request\n    response = self._conn.request(method, url, body=body, headers=headers, timeout=self._client_config.timeout)\n               ^^^^^^^^^^^^^^^^^^^^^^^^^^^^^^^^^^^^^^^^^^^^^^^^^^^^^^^^^^^^^^^^^^^^^^^^^^^^^^^^^^^^^^^^^^^^^^^^\n  File \"/opt/anaconda3/lib/python3.12/site-packages/urllib3/_request_methods.py\", line 135, in request\n    return self.request_encode_url(\n           ^^^^^^^^^^^^^^^^^^^^^^^^\n  File \"/opt/anaconda3/lib/python3.12/site-packages/urllib3/_request_methods.py\", line 182, in request_encode_url\n    return self.urlopen(method, url, **extra_kw)\n           ^^^^^^^^^^^^^^^^^^^^^^^^^^^^^^^^^^^^^\n  File \"/opt/anaconda3/lib/python3.12/site-packages/urllib3/poolmanager.py\", line 443, in urlopen\n    response = conn.urlopen(method, u.request_uri, **kw)\n               ^^^^^^^^^^^^^^^^^^^^^^^^^^^^^^^^^^^^^^^^^\n  File \"/opt/anaconda3/lib/python3.12/site-packages/urllib3/connectionpool.py\", line 873, in urlopen\n    return self.urlopen(\n           ^^^^^^^^^^^^^\n  File \"/opt/anaconda3/lib/python3.12/site-packages/urllib3/connectionpool.py\", line 873, in urlopen\n    return self.urlopen(\n           ^^^^^^^^^^^^^\n  File \"/opt/anaconda3/lib/python3.12/site-packages/urllib3/connectionpool.py\", line 873, in urlopen\n    return self.urlopen(\n           ^^^^^^^^^^^^^\n  File \"/opt/anaconda3/lib/python3.12/site-packages/urllib3/connectionpool.py\", line 843, in urlopen\n    retries = retries.increment(\n              ^^^^^^^^^^^^^^^^^^\n  File \"/opt/anaconda3/lib/python3.12/site-packages/urllib3/util/retry.py\", line 519, in increment\n    raise MaxRetryError(_pool, url, reason) from reason  # type: ignore[arg-type]\n    ^^^^^^^^^^^^^^^^^^^^^^^^^^^^^^^^^^^^^^^^^^^^^^^^^^^\n"}, "start": 1739642300334, "stop": 1739642300356}], "start": 1739642294235, "stop": 1739642300358, "uuid": "305e97f1-0bb2-4d77-9850-52b074a8824d", "historyId": "51f818ea9aa144bec64354dac864d1e1", "fullName": "Website Navigation: Navigate through different pages", "labels": [{"name": "severity", "value": "normal"}, {"name": "feature", "value": "Website Navigation"}, {"name": "framework", "value": "behave"}, {"name": "language", "value": "cpython3"}]}